[2023-04-08 03:01:10,329] {taskinstance.py:1159} INFO - Dependencies all met for <TaskInstance: user_processing.create_table manual__2023-04-08T03:01:08.260107+00:00 [queued]>
[2023-04-08 03:01:10,343] {taskinstance.py:1159} INFO - Dependencies all met for <TaskInstance: user_processing.create_table manual__2023-04-08T03:01:08.260107+00:00 [queued]>
[2023-04-08 03:01:10,345] {taskinstance.py:1356} INFO - 
--------------------------------------------------------------------------------
[2023-04-08 03:01:10,346] {taskinstance.py:1357} INFO - Starting attempt 1 of 1
[2023-04-08 03:01:10,347] {taskinstance.py:1358} INFO - 
--------------------------------------------------------------------------------
[2023-04-08 03:01:10,356] {taskinstance.py:1377} INFO - Executing <Task(PostgresOperator): create_table> on 2023-04-08 03:01:08.260107+00:00
[2023-04-08 03:01:10,362] {standard_task_runner.py:52} INFO - Started process 424 to run task
[2023-04-08 03:01:10,367] {standard_task_runner.py:79} INFO - Running: ['***', 'tasks', 'run', 'user_processing', 'create_table', 'manual__2023-04-08T03:01:08.260107+00:00', '--job-id', '15', '--raw', '--subdir', 'DAGS_FOLDER/user_processing.py', '--cfg-path', '/tmp/tmpg3e3ed0i', '--error-file', '/tmp/tmpz2qc81a2']
[2023-04-08 03:01:10,370] {standard_task_runner.py:80} INFO - Job 15: Subtask create_table
[2023-04-08 03:01:10,434] {task_command.py:369} INFO - Running <TaskInstance: user_processing.create_table manual__2023-04-08T03:01:08.260107+00:00 [running]> on host a51dc0b874ee
[2023-04-08 03:01:10,496] {taskinstance.py:1571} INFO - Exporting the following env vars:
AIRFLOW_CTX_DAG_OWNER=***
AIRFLOW_CTX_DAG_ID=user_processing
AIRFLOW_CTX_TASK_ID=create_table
AIRFLOW_CTX_EXECUTION_DATE=2023-04-08T03:01:08.260107+00:00
AIRFLOW_CTX_TRY_NUMBER=1
AIRFLOW_CTX_DAG_RUN_ID=manual__2023-04-08T03:01:08.260107+00:00
[2023-04-08 03:01:10,522] {taskinstance.py:1889} ERROR - Task failed with exception
Traceback (most recent call last):
  File "/home/airflow/.local/lib/python3.7/site-packages/airflow/providers/postgres/operators/postgres.py", line 92, in execute
    self.hook.run(self.sql, self.autocommit, parameters=self.parameters)
  File "/home/airflow/.local/lib/python3.7/site-packages/airflow/hooks/dbapi.py", line 181, in run
    with closing(self.get_conn()) as conn:
  File "/home/airflow/.local/lib/python3.7/site-packages/airflow/providers/postgres/hooks/postgres.py", line 86, in get_conn
    conn = deepcopy(self.connection or self.get_connection(conn_id))
  File "/home/airflow/.local/lib/python3.7/site-packages/airflow/hooks/base.py", line 67, in get_connection
    conn = Connection.get_connection_from_secrets(conn_id)
  File "/home/airflow/.local/lib/python3.7/site-packages/airflow/models/connection.py", line 430, in get_connection_from_secrets
    raise AirflowNotFoundException(f"The conn_id `{conn_id}` isn't defined")
airflow.exceptions.AirflowNotFoundException: The conn_id `postgres` isn't defined
[2023-04-08 03:01:10,526] {taskinstance.py:1400} INFO - Marking task as FAILED. dag_id=user_processing, task_id=create_table, execution_date=20230408T030108, start_date=20230408T030110, end_date=20230408T030110
[2023-04-08 03:01:10,535] {standard_task_runner.py:97} ERROR - Failed to execute job 15 for task create_table (The conn_id `postgres` isn't defined; 424)
[2023-04-08 03:01:10,579] {local_task_job.py:156} INFO - Task exited with return code 1
[2023-04-08 03:01:10,629] {local_task_job.py:273} INFO - 0 downstream tasks scheduled from follow-on schedule check
